Workbook
Name Anskaffelsesnavn: Lister!$E$7
Name Delleveranse: '5. Krav til prod.'!$G$10
Name Dokumentnavn: Lister!$E$9
Name Dokumentnummer: Lister!$E$8
Name kolonnematch_vektingsoppslag: [1]Vektingsoppslag!$D$1
Name kravtype: Lister!$G$43:$G$44
Name navn_Anskaffelseskode: Lister!$E$6
Name navn_atc: '5. Krav til prod.'!$G$22:$I$22
Name navn_bruksomrade: '5. Krav til prod.'!$G$25
Name navn_delleveranse: '5. Krav til prod.'!$G$18
Name navn_leverandornavn: '4. Krav til lev.'!$G$19
Name navn_leverandornavn_produktfane: '5. Krav til prod.'!$G$17
Name navn_Navn_på_kravspesifikasjon: Lister!$E$10
Name navn_undergruppe: '5. Krav til prod.'!$G$24
Name navn_virkestoff: '5. Krav til prod.'!$G$23
Name oppfylt: Lister!$E$44:$E$44
Name toggle_betingetFormatering: Lister!$A$26

Sheet 1. Innhold
B1: =CONCATENATE(navn_Anskaffelseskode," Vedlegg ",Dokumentnummer," Kravspesifikasjon ", Dokumentnavn) -> 2301d Vedlegg 02 Kravspesifikasjon Uregistrerte legemidler
B4: 1. Innhold
B6: Dette dokumentet består av:
B7: - Forklaring til kravspesifikasjonen
B8: - Anskaffelsens innhold
B9: - Krav til leverandøren
B10: - Krav til produktene

Sheet 2. Forklaring til kravspes.
B3: 2. Forklaring til kravspesifikasjonen
B5: Oppdragsgiver har angitt formålet med anskaffelsen, og sine krav og behov i kravspesifikasjonen. Dette danner grunnlaget for Tilbyderens tilbud.
B6: I kravspesifikasjonen er det lagt vekt på å beskrive de behov som skal dekkes. Tilbyderen skal med utgangspunkt i kravspesifikasjonens rammer gi tilbud på forespurte produkter og beskrive hvordan kravene som stilles vil bli oppfylt. Tilbyderen er ansvarlig for at leveransen til enhver tid dekker kravene som er spesifisert i Vedlegg 02.
B8: Tilbyderen skal besvare kravene direkte i kravspesifikasjonen og henvise til egne vedlegg ved behov. En tydelig og poengtert besvarelse vil lette Oppdragsgivers evaluering av tilbudet og sikre at korrekt informasjon blir brukt ved evalueringen. Det skal også her henvises til hvor i besvarelsen en eventuell utdypende beskrivelse, som kan ha betydning ved evalueringen, finnes. Henvisningen skal gi informasjon om navn på dokument, side og avsnitt. En besvarelse som for eksempel "se katalog / brosjyre" er ikke ønskelig, og kan føre til at tilbudet blir evaluert uten at Oppdragsgiver har kjennskap til alle egenskaper ved tilbudet / produktet.
B10: Kravene er utformet som SKAL-krav ("S") og BØR-krav ("B"). Dette kommer frem i kolonnen "kravtype" i tabellene.
B12: SKAL-krav er minstekrav til produktet. Alle SKAL-krav må være oppfylt for at produktet skal bli evaluert. Manglende oppfyllelse av SKAL-krav er et vesentlig avvik fra kravspesifikasjonen og vil medføre at tilbudet for det aktuelle produktet, eller den delleveransen produktet tilhører, avvises fra konkurransen. SKAL-krav vil ikke bli evaluert utover om det er oppfylt eller ikke. Tilbyderen skal angi svar 'JA' eller velge et eventuelt alternativ i nedtrekksmenyen for om det tilbudte produkt oppfyller kravet som angis i punktet.
B14: BØR-krav er momenter som vil bli tillagt vekt i evalueringen av kvalitet (tildelingskriteriene X, Z og Y), og de nærmere angitte underkriterier (se kolonne "Underkriterium"). For BØR-krav vurderer Oppdragsgiver hvor godt de aktuelle kravene er oppfylt. Produkter som oppfyller BØR-kravene best vil få flest poeng.
B16: Tilbyderen skal fylle ut de hvite feltene i kravspesifikasjonen. Tilbyderen skal ikke legge til eller slette verken linjer eller kolonner i kravspesifikasjonen.
B17: Der det leveres tilbud på delleveransenummer ikke er listet i arkfane 3, bes leverandør legge til korrekt informasjon i arkfane 3.
B19: Oppdragsgiver har gitt hver linje i kravspesifikasjonen et unikt identifikasjonsnummer (kolonne B). Dette for lettere å kunne henvise til riktig punkt i kravspesifikasjonen ved behov.
B21: Dersom Tilbyderen har behov for eller ønsker å laste opp produktinformasjon, kan dette gjøres i PharmaWeb. Det vises til konkurransegrunnlagets Vedlegg 04 Bilag 4 pkt. 8.
B23: 2.1 - Leverandør
... B26: Det skal leveres én besvarelse per delleveranse (ATC/substans/undergruppe/bruksområde). Arkfane 'Krav til prod.'

Sheet 3. Anskaffelsen
B3: 3. Beskrivelse av anskaffelsens innhold
B5: Det ønskes tilbud på følgende delleveranser innenfor området
B6: =CONCATENATE(navn_Anskaffelseskode," ",Dokumentnavn," ",Dokumentnummer," ",navn_Navn_på_kravspesifikasjon) -> 2301d Uregistrerte legemidler 02 | J6: SKJULES? HVOR MANGE TRENGS | K6: Kravsett for delleveranse - se arkfane 5. Krav til prod
B7: Delleveranse | C7: ATC | D7: Virkestoff | E7: Legemiddelformgruppe | F7: Bruksparameter Sykehusinnkjøp | G7: Parallell avtale Ja/nei | H7: Begrunnelse for parallell avtale | I7: Forventet lager hos grossist i Norge (B180, G2021) (inntil antall dager) | J7: Kravsett for delleveranse | K7: Kravsett 1 | L7: Kravsett 2 | M7: Kravsett 3 | N7: Kravsett 4
B8: 1 | C8: A03AD01 | D8: Papaverin | E8: Injeksjon | G8: Nei | H8: (Ikke angitt) | J8: =tabell_anskaffelsens_innhold[[#This Row],[Kravsett 1]]&" "&tabell_anskaffelsens_innhold[[#This Row],[Kravsett 2]]&" "&tabell_anskaffelsens_innhold[[#This Row],[Kravsett 3]]&" "&tabell_anskaffelsens_innhold[[#This Row],[Kravsett 4]] -> Generelle Inj/inf A03AD01 Papaverin | K8: Generelle | L8: Inj/inf | M8: A03AD01 Papaverin
B9: 2 | C9: A11BA | D9: Multivitaminer | E9: Mikstur/dråper | G9: Nei | H9: (Ikke angitt) | J9: =tabell_anskaffelsens_innhold[[#This Row],[Kravsett 1]]&" "&tabell_anskaffelsens_innhold[[#This Row],[Kravsett 2]]&" "&tabell_anskaffelsens_innhold[[#This Row],[Kravsett 3]]&" "&tabell_anskaffelsens_innhold[[#This Row],[Kravsett 4]] -> Generelle Mikstur/dråper | K9: Generelle | L9: Mikstur/dråper
B10: 3 | C10: A11CC05 | D10: Kolekalsiferol | E10: Injeksjon | G10: Nei | H10: (Ikke angitt) | J10: =tabell_anskaffelsens_innhold[[#This Row],[Kravsett 1]]&" "&tabell_anskaffelsens_innhold[[#This Row],[Kravsett 2]]&" "&tabell_anskaffelsens_innhold[[#This Row],[Kravsett 3]]&" "&tabell_anskaffelsens_innhold[[#This Row],[Kravsett 4]] -> Generelle Inj/inf | K10: Generelle | L10: Inj/inf
B11: 4 | C11: A11DA01 | D11: Tiamin | E11: Injeksjon | F11: IM, høy dose | G11: Nei | H11: (Ikke angitt) | J11: =tabell_anskaffelsens_innhold[[#This Row],[Kravsett 1]]&" "&tabell_anskaffelsens_innhold[[#This Row],[Kravsett 2]]&" "&tabell_anskaffelsens_innhold[[#This Row],[Kravsett 3]]&" "&tabell_anskaffelsens_innhold[[#This Row],[Kravsett 4]] -> Generelle Inj/inf | K11: Generelle | L11: Inj/inf
B12: 5 | C12: A11DA01 | D12: Tiamin | E12: Tablett/kapsel | F12: Høy styrke | G12: Nei | H12: (Ikke angitt) | J12: =tabell_anskaffelsens_innhold[[#This Row],[Kravsett 1]]&" "&tabell_anskaffelsens_innhold[[#This Row],[Kravsett 2]]&" "&tabell_anskaffelsens_innhold[[#This Row],[Kravsett 3]]&" "&tabell_anskaffelsens_innhold[[#This Row],[Kravsett 4]] -> Generelle Tabletter/kapsler | K12: Generelle | L12: Tabletter/kapsler
B13: 6 | C13: A11EB | D13: Askorbinsyre, Tiamin, Riboflavin, Nikotinamid, Pyridoksin, Glukose | E13: Infusjonskonsentrat | G13: Nei | H13: (Ikke angitt) | J13: =tabell_anskaffelsens_innhold[[#This Row],[Kravsett 1]]&" "&tabell_anskaffelsens_innhold[[#This Row],[Kravsett 2]]&" "&tabell_anskaffelsens_innhold[[#This Row],[Kravsett 3]]&" "&tabell_anskaffelsens_innhold[[#This Row],[Kravsett 4]] -> Generelle Inj/inf | K13: Generelle | L13: Inj/inf
B14: 7 | C14: A11EB | D14: Askorbinsyre, Tiamin, Riboflavin, Nikotinamid, Pyridoksin | E14: Injeksjon | F14: Intramuskulært | G14: Nei | H14: (Ikke angitt) | J14: =tabell_anskaffelsens_innhold[[#This Row],[Kravsett 1]]&" "&tabell_anskaffelsens_innhold[[#This Row],[Kravsett 2]]&" "&tabell_anskaffelsens_innhold[[#This Row],[Kravsett 3]]&" "&tabell_anskaffelsens_innhold[[#This Row],[Kravsett 4]] -> Generelle Inj/inf | K14: Generelle | L14: Inj/inf
B15: 8 | C15: A11HA03 | D15: Tokoferol | E15: Mikstur/dråper | G15: Nei | H15: (Ikke angitt) | J15: =tabell_anskaffelsens_innhold[[#This Row],[Kravsett 1]]&" "&tabell_anskaffelsens_innhold[[#This Row],[Kravsett 2]]&" "&tabell_anskaffelsens_innhold[[#This Row],[Kravsett 3]]&" "&tabell_anskaffelsens_innhold[[#This Row],[Kravsett 4]] -> Generelle Mikstur/dråper | K15: Generelle | L15: Mikstur/dråper
B16: 9 | C16: A11JA | D16: Vitamin A, Vitamin D2, Cyanokobalamin, Kolin | E16: Mikstur/dråper | G16: Nei | H16: (Ikke angitt) | J16: =tabell_anskaffelsens_innhold[[#This Row],[Kravsett 1]]&" "&tabell_anskaffelsens_innhold[[#This Row],[Kravsett 2]]&" "&tabell_anskaffelsens_innhold[[#This Row],[Kravsett 3]]&" "&tabell_anskaffelsens_innhold[[#This Row],[Kravsett 4]] -> Generelle Mikstur/dråper | K16: Generelle | L16: Mikstur/dråper
B17: 10 | C17: A12AA03 | D17: Kalsiumglukonat | E17: Injeksjon | G17: Nei | H17: (Ikke angitt) | I17: 180 | J17: =tabell_anskaffelsens_innhold[[#This Row],[Kravsett 1]]&" "&tabell_anskaffelsens_innhold[[#This Row],[Kravsett 2]]&" "&tabell_anskaffelsens_innhold[[#This Row],[Kravsett 3]]&" "&tabell_anskaffelsens_innhold[[#This Row],[Kravsett 4]] -> Generelle Inj/inf | K17: Generelle | L17: Inj/inf
B18: 11 | C18: A12CC | D18: Magnesiumglyserfosfat | E18: Mikstur/dråper | G18: Nei | H18: (Ikke angitt) | J18: =tabell_anskaffelsens_innhold[[#This Row],[Kravsett 1]]&" "&tabell_anskaffelsens_innhold[[#This Row],[Kravsett 2]]&" "&tabell_anskaffelsens_innhold[[#This Row],[Kravsett 3]]&" "&tabell_anskaffelsens_innhold[[#This Row],[Kravsett 4]] -> Generelle Mikstur/dråper | K18: Generelle | L18: Mikstur/dråper
B19: 12 | C19: A14AA08 | D19: Oksandrolon | E19: Tablett/kapsel | G19: Nei | H19: (Ikke angitt) | I19: 30 | J19: =tabell_anskaffelsens_innhold[[#This Row],[Kravsett 1]]&" "&tabell_anskaffelsens_innhold[[#This Row],[Kravsett 2]]&" "&tabell_anskaffelsens_innhold[[#This Row],[Kravsett 3]]&" "&tabell_anskaffelsens_innhold[[#This Row],[Kravsett 4]] -> Generelle Tabletter/kapsler | K19: Generelle | L19: Tabletter/kapsler
B20: 13 | C20: A16AA01 | D20: Levokarnitin | E20: Injeksjon | G20: Nei | H20: (Ikke angitt) | I20: 30 | J20: =tabell_anskaffelsens_innhold[[#This Row],[Kravsett 1]]&" "&tabell_anskaffelsens_innhold[[#This Row],[Kravsett 2]]&" "&tabell_anskaffelsens_innhold[[#This Row],[Kravsett 3]]&" "&tabell_anskaffelsens_innhold[[#This Row],[Kravsett 4]] -> Generelle Inj/inf | K20: Generelle | L20: Inj/inf
B21: 14 | C21: B01AB01 | D21: Heparin | E21: Infusjonskonsentrat | F21: 1000IE Uten konservering | G21: Nei | H21: (Ikke angitt) | J21: =tabell_anskaffelsens_innhold[[#This Row],[Kravsett 1]]&" "&tabell_anskaffelsens_innhold[[#This Row],[Kravsett 2]]&" "&tabell_anskaffelsens_innhold[[#This Row],[Kravsett 3]]&" "&tabell_anskaffelsens_innhold[[#This Row],[Kravsett 4]] -> Generelle Inj/inf | K21: Generelle | L21: Inj/inf
B22: 15 | C22: B01AB01 | D22: Heparin | E22: Injeksjon | F22: 5000IE uten konservering | G22: Nei | H22: (Ikke angitt) | J22: =tabell_anskaffelsens_innhold[[#This Row],[Kravsett 1]]&" "&tabell_anskaffelsens_innhold[[#This Row],[Kravsett 2]]&" "&tabell_anskaffelsens_innhold[[#This Row],[Kravsett 3]]&" "&tabell_anskaffelsens_innhold[[#This Row],[Kravsett 4]] -> Generelle Inj/inf | K22: Generelle | L22: Inj/inf
B23: 16 | C23: B01AB01 | D23: Heparin | E23: Injeksjon | F23: 50IE uten konservering | G23: Nei | H23: (Ikke angitt) | J23: =tabell_anskaffelsens_innhold[[#This Row],[Kravsett 1]]&" "&tabell_anskaffelsens_innhold[[#This Row],[Kravsett 2]]&" "&tabell_anskaffelsens_innhold[[#This Row],[Kravsett 3]]&" "&tabell_anskaffelsens_innhold[[#This Row],[Kravsett 4]] -> Generelle Inj/inf | K23: Generelle | L23: Inj/inf
B24: 17 | C24: B02BA01 | D24: Fytomenadion | E24: Injeksjon | F24: Høydose | G24: Nei | H24: (Ikke angitt) | I24: 30 | J24: =tabell_anskaffelsens_innhold[[#This Row],[Kravsett 1]]&" "&tabell_anskaffelsens_innhold[[#This Row],[Kravsett 2]]&" "&tabell_anskaffelsens_innhold[[#This Row],[Kravsett 3]]&" "&tabell_anskaffelsens_innhold[[#This Row],[Kravsett 4]] -> Generelle Inj/inf | K24: Generelle | L24: Inj/inf
B25: 18 | C25: B02BA01 | D25: Fytomenadion | E25: Mikstur/dråper | G25: Nei | H25: (Ikke angitt) | J25: =tabell_anskaffelsens_innhold[[#This Row],[Kravsett 1]]&" "&tabell_anskaffelsens_innhold[[#This Row],[Kravsett 2]]&" "&tabell_anskaffelsens_innhold[[#This Row],[Kravsett 3]]&" "&tabell_anskaffelsens_innhold[[#This Row],[Kravsett 4]] -> Generelle Mikstur/dråper | K25: Generelle | L25: Mikstur/dråper
B26: 19 | C26: B02BD | D26: Faktor X, Faktor IX | E26: Tørrstoff | G26: Nei | H26: (Ikke angitt) | J26: =tabell_anskaffelsens_innhold[[#This Row],[Kravsett 1]]&" "&tabell_anskaffelsens_innhold[[#This Row],[Kravsett 2]]&" "&tabell_anskaffelsens_innhold[[#This Row],[Kravsett 3]]&" "&tabell_anskaffelsens_innhold[[#This Row],[Kravsett 4]] -> Generelle Tørrstoff | K26: Generelle | L26: Tørrstoff
B27: 20 | C27: B05XA16 | D27: Kaliumklorid, Magnesiumklorid, Prokainhydroklorid | E27: Infusjonskonsentrat | G27: Nei | H27: (Ikke angitt) | I27: 30 | J27: =tabell_anskaffelsens_innhold[[#This Row],[Kravsett 1]]&" "&tabell_anskaffelsens_innhold[[#This Row],[Kravsett 2]]&" "&tabell_anskaffelsens_innhold[[#This Row],[Kravsett 3]]&" "&tabell_anskaffelsens_innhold[[#This Row],[Kravsett 4]] -> Generelle Inj/inf | K27: Generelle | L27: Inj/inf
B28: 21 | C28: C01BB02 | D28: Meksiletin | E28: Tablett/kapsel | F28: mot hjertearytmi | G28: Nei | H28: (Ikke angitt) | J28: =tabell_anskaffelsens_innhold[[#This Row],[Kravsett 1]]&" "&tabell_anskaffelsens_innhold[[#This Row],[Kravsett 2]]&" "&tabell_anskaffelsens_innhold[[#This Row],[Kravsett 3]]&" "&tabell_anskaffelsens_innhold[[#This Row],[Kravsett 4]] -> Generelle Tabletter/kapsler | K28: Generelle | L28: Tabletter/kapsler
B29: 22 | C29: C01CA07 | D29: Dobutamin | E29: Infusjon | G29: Nei | H29: (Ikke angitt) | J29: =tabell_anskaffelsens_innhold[[#This Row],[Kravsett 1]]&" "&tabell_anskaffelsens_innhold[[#This Row],[Kravsett 2]]&" "&tabell_anskaffelsens_innhold[[#This Row],[Kravsett 3]]&" "&tabell_anskaffelsens_innhold[[#This Row],[Kravsett 4]] -> Generelle Inj/inf Infusjon | K29: Generelle | L29: Inj/inf | M29: Infusjon
B30: 24 | C30: C02AC01 | D30: Klonidin | E30: Tablett/kapsel | G30: Nei | H30: (Ikke angitt) | J30: =tabell_anskaffelsens_innhold[[#This Row],[Kravsett 1]]&" "&tabell_anskaffelsens_innhold[[#This Row],[Kravsett 2]]&" "&tabell_anskaffelsens_innhold[[#This Row],[Kravsett 3]]&" "&tabell_anskaffelsens_innhold[[#This Row],[Kravsett 4]] -> Generelle Tabletter/kapsler C02AC01 Klonidin | K30: Generelle | L30: Tabletter/kapsler | M30: C02AC01 Klonidin
B31: 25 | C31: C02DB01 | D31: Dihydralazin | E31: Tørrstoff | G31: Nei | H31: (Ikke angitt) | J31: =tabell_anskaffelsens_innhold[[#This Row],[Kravsett 1]]&" "&tabell_anskaffelsens_innhold[[#This Row],[Kravsett 2]]&" "&tabell_anskaffelsens_innhold[[#This Row],[Kravsett 3]]&" "&tabell_anskaffelsens_innhold[[#This Row],[Kravsett 4]] -> Generelle Tørrstoff | K31: Generelle | L31: Tørrstoff
B32: 26 | C32: C03DA02 | D32: Kanrenoinsyre | E32: Injeksjon | G32: Nei | H32: (Ikke angitt) | I32: 30 | J32: =tabell_anskaffelsens_innhold[[#This Row],[Kravsett 1]]&" "&tabell_anskaffelsens_innhold[[#This Row],[Kravsett 2]]&" "&tabell_anskaffelsens_innhold[[#This Row],[Kravsett 3]]&" "&tabell_anskaffelsens_innhold[[#This Row],[Kravsett 4]] -> Generelle Inj/inf | K32: Generelle | L32: Inj/inf
B33: 27 | C33: C05 | D33: Blodigler | E33: Topikal plaster/svamp/klut | G33: Nei | H33: (Ikke angitt) | J33: =tabell_anskaffelsens_innhold[[#This Row],[Kravsett 1]]&" "&tabell_anskaffelsens_innhold[[#This Row],[Kravsett 2]]&" "&tabell_anskaffelsens_innhold[[#This Row],[Kravsett 3]]&" "&tabell_anskaffelsens_innhold[[#This Row],[Kravsett 4]] -> Generelle | K33: Generelle
B34: 28 | C34: C05BB02 | D34: Polidokanol | E34: Injeksjon | G34: Ja | H34: Ulike styrker | J34: =tabell_anskaffelsens_innhold[[#This Row],[Kravsett 1]]&" "&tabell_anskaffelsens_innhold[[#This Row],[Kravsett 2]]&" "&tabell_anskaffelsens_innhold[[#This Row],[Kravsett 3]]&" "&tabell_anskaffelsens_innhold[[#This Row],[Kravsett 4]] -> Generelle Inj/inf | K34: Generelle | L34: Inj/inf
B35: 29 | C35: C08CA05 | D35: Nifedipin | E35: Mikstur/dråper | G35: Nei | H35: (Ikke angitt) | I35: 30 | J35: =tabell_anskaffelsens_innhold[[#This Row],[Kravsett 1]]&" "&tabell_anskaffelsens_innhold[[#This Row],[Kravsett 2]]&" "&tabell_anskaffelsens_innhold[[#This Row],[Kravsett 3]]&" "&tabell_anskaffelsens_innhold[[#This Row],[Kravsett 4]] -> Generelle Mikstur/dråper | K35: Generelle | L35: Mikstur/dråper
B36: 30 | C36: C08DA01 | D36: Verapamil | E36: Injeksjon | G36: Nei | H36: (Ikke angitt) | I36: 150 | J36: =tabell_anskaffelsens_innhold[[#This Row],[Kravsett 1]]&" "&tabell_anskaffelsens_innhold[[#This Row],[Kravsett 2]]&" "&tabell_anskaffelsens_innhold[[#This Row],[Kravsett 3]]&" "&tabell_anskaffelsens_innhold[[#This Row],[Kravsett 4]] -> Generelle Inj/inf | K36: Generelle | L36: Inj/inf
B37: 31 | C37: D01AE02 | D37: Metylrosanilin | E37: Topikal liniment | G37: Nei | H37: (Ikke angitt) | J37: =tabell_anskaffelsens_innhold[[#This Row],[Kravsett 1]]&" "&tabell_anskaffelsens_innhold[[#This Row],[Kravsett 2]]&" "&tabell_anskaffelsens_innhold[[#This Row],[Kravsett 3]]&" "&tabell_anskaffelsens_innhold[[#This Row],[Kravsett 4]] -> Generelle | K37: Generelle
B38: 32 | C38: D02AC | D38: Vaselin | E38: Topikal krem/salve/gel | F38: Steril | G38: Nei | H38: (Ikke angitt) | J38: =tabell_anskaffelsens_innhold[[#This Row],[Kravsett 1]]&" "&tabell_anskaffelsens_innhold[[#This Row],[Kravsett 2]]&" "&tabell_anskaffelsens_innhold[[#This Row],[Kravsett 3]]&" "&tabell_anskaffelsens_innhold[[#This Row],[Kravsett 4]] -> Generelle | K38: Generelle
B39: 33 | C39: D08AG02 | D39: Povidon, jodert | E39: Topikal liniment | G39: Nei | H39: (Ikke angitt) | J39: =tabell_anskaffelsens_innhold[[#This Row],[Kravsett 1]]&" "&tabell_anskaffelsens_innhold[[#This Row],[Kravsett 2]]&" "&tabell_anskaffelsens_innhold[[#This Row],[Kravsett 3]]&" "&tabell_anskaffelsens_innhold[[#This Row],[Kravsett 4]] -> Generelle D08AG02 Povidon, jodert, til bruk på hud | K39: Generelle | L39: D08AG02 Povidon, jodert, til bruk på hud
B40: 34 | C40: D08AG02 | D40: Povidon, jodert | E40: Topikal liniment | F40: Skrubb, med glyserol | G40: Nei | H40: (Ikke angitt) | J40: =tabell_anskaffelsens_innhold[[#This Row],[Kravsett 1]]&" "&tabell_anskaffelsens_innhold[[#This Row],[Kravsett 2]]&" "&tabell_anskaffelsens_innhold[[#This Row],[Kravsett 3]]&" "&tabell_anskaffelsens_innhold[[#This Row],[Kravsett 4]] -> Generelle D08AG02 Povidon, jodert, til bruk på hud, skrubb, med glyserol | K40: Generelle | L40: D08AG02 Povidon, jodert, til bruk på hud, skrubb, med glyserol
B41: 35 | C41: D08AL01 | D41: Sølvnitrat | E41: Topikal krem/salve/gel | F41: Stift | G41: Nei | H41: (Ikke angitt) | J41: =tabell_anskaffelsens_innhold[[#This Row],[Kravsett 1]]&" "&tabell_anskaffelsens_innhold[[#This Row],[Kravsett 2]]&" "&tabell_anskaffelsens_innhold[[#This Row],[Kravsett 3]]&" "&tabell_anskaffelsens_innhold[[#This Row],[Kravsett 4]] -> Generelle | K41: Generelle
B42: 36 | C42: G01AX03 | D42: Polikresulen | E42: Vaginal | G42: Nei | H42: (Ikke angitt) | J42: =tabell_anskaffelsens_innhold[[#This Row],[Kravsett 1]]&" "&tabell_anskaffelsens_innhold[[#This Row],[Kravsett 2]]&" "&tabell_anskaffelsens_innhold[[#This Row],[Kravsett 3]]&" "&tabell_anskaffelsens_innhold[[#This Row],[Kravsett 4]] -> Generelle | K42: Generelle
B43: 37 | C43: G02AB01 | D43: Metylergometrin | E43: Injeksjon | G43: Nei | H43: (Ikke angitt) | I43: 180 | J43: =tabell_anskaffelsens_innhold[[#This Row],[Kravsett 1]]&" "&tabell_anskaffelsens_innhold[[#This Row],[Kravsett 2]]&" "&tabell_anskaffelsens_innhold[[#This Row],[Kravsett 3]]&" "&tabell_anskaffelsens_innhold[[#This Row],[Kravsett 4]] -> Generelle Inj/inf | K43: Generelle | L43: Inj/inf
...

Sheet 4. Krav til lev.
D3: =CONCATENATE(navn_Anskaffelseskode," Vedlegg ",Dokumentnummer," Kravspesifikasjon ", Dokumentnavn) -> 2301d Vedlegg 02 Kravspesifikasjon Uregistrerte legemidler
D5: 4. Krav til leverandøren
D6: NB: Det må leveres én besvarelse per leverandør
D7: Tildlingskriterier/underkriterier | G7: Vekting
D8: =Lister!I43 -> Pris (P) | G8: =Lister!J43 -> 0.35
D9: =Lister!I44 -> Brukervennlighet, pakninger og produktspekter (PP) | G9: =Lister!J44 -> 0.45
D10: =Lister!I45 -> Leveringssikkerhet: Lager (LP1) | G10: =Lister!J45 -> 0.15
D11: =Lister!I46 -> Leveringssikkerhet: Salg i flere land (LP2) | G11: =Lister!J46 -> 0.05
D12: =Lister!I47 -> Leveringssikkerhet: Fellesnordisk pakning (LP3) | G12: =Lister!J47 -> 0
D13: =Lister!I48 -> Miljø på leverandørnivå: XX (ML1) | G13: =Lister!J48 -> 0
D14: =Lister!I49 -> Miljø på produktnivå: XX (MP1) | G14: =Lister!J49 -> 0
D15: =Lister!I50 -> Pakninger og produktspekter (PP) | G15: =Lister!J50 -> 0
G16: SUM VEKTING <> 100% (FEILMELDING FJERNES NÅR LISTE = 100%) OPPDATER I EGET ARK!
D17: Informasjon om leverandør:
D19: Leverandørnavn:
D20: Kontaktperson for forsyningssikkerhet:
D21: E-postadresse ved leveringssvikt:
D22: Telefonnummer ved leveringssvikt:
D23: E-postadresse til logistikkavdeling:
D25: Oppdragsgivers kravspesifikasjon | J25: Tilbyderens besvarelse
B26: Anskaffelse | C26: Delleveranse | D26: Ref. | E26: Kravsett | F26: Overskrift for krav | G26: Beskrivelse av krav | H26: Krav- type | I26: Tildelingskriterier | J26: Utfyllende informasjon til tilbyder | K26: Velg svaralternativ i listen | L26: Utfyllende besvarelse | M26: Evt. lenke eller henvisning til vedlegg
B27: =navn_Anskaffelseskode -> 2301d | C27: =navn_delleveranse -> 0 | D27: 4.01 | E27: Leverandør | F27: Leveringssikkerhet | G27: Leverandøren forplikter seg til å opprette og forvalte 90 dager sikkerhetslager i EU/EØS av tilbudte produkter. Sikkerhetslageret skal være avsatt til det norske markedet. | H27: S | J27: Kontraktskrav til forvaltning av sikkerhetslager fremgår av rammeavtalen punkt 7.6.2.
B28: =navn_Anskaffelseskode -> 2301d | C28: =navn_delleveranse -> 0 | D28: 4.02 | E28: Leverandør | F28: Leveringssikkerhet | G28: Sykehusinnkjøp skal kunne revidere sikkerhetslager, fastsatt i krav 4.01, senest en måned før avtalestart. Ved varer med høyere beredskap enn 1 måned ved avtalestart skal man kunne fremvise en produksjonsplan senest 3 måneder før avtaleoppstart for nødvendig lageroppbygging. Dette kravet gjelder kun ny anbudsvinner, da eksisterende avtaleleverandør allerede har varer hos grossist og apotek/HF. | H28: S | J28: 30 dagers sikkerhetslager er inkludert.

Sheet 5. Krav til prod.
D3: =CONCATENATE(navn_Anskaffelseskode," Vedlegg ",Dokumentnummer," Kravspesifikasjon ", Dokumentnavn) -> 2301d Vedlegg 02 Kravspesifikasjon Uregistrerte legemidler
D5: 5. Krav til produktene
D6: Tildlingskriterier/underkriterier | G6: Vekting
D7: =Lister!I43 -> Pris (P) | G7: =Lister!J43 -> 0.35
D8: =Lister!I44 -> Brukervennlighet, pakninger og produktspekter (PP) | G8: =Lister!J44 -> 0.45
D9: =Lister!I45 -> Leveringssikkerhet: Lager (LP1) | G9: =Lister!J45 -> 0.15
D10: =Lister!I46 -> Leveringssikkerhet: Salg i flere land (LP2) | G10: =Lister!J46 -> 0.05
D11: =Lister!I47 -> Leveringssikkerhet: Fellesnordisk pakning (LP3) | G11: =Lister!J47 -> 0
D12: =Lister!I48 -> Miljø på leverandørnivå: XX (ML1) | G12: =Lister!J48 -> 0
D13: =Lister!I49 -> Miljø på produktnivå: XX (MP1) | G13: =Lister!J49 -> 0
D14: =Lister!I50 -> Pakninger og produktspekter (PP) | G14: =Lister!J50 -> 0
G15: SUM VEKTING <> 100% (FEILMELDING FJERNES NÅR LISTE = 100%) OPPDATER I EGET ARK!
D16: Informasjon om tilbudt produkt/produkter:
D17: Leverandørnavn:
D18: Delleveranse (som angitt i ark 3)
D19: Kravsett for delleveranse | F19: Kravsett | G19: =_xlfn.XLOOKUP(navn_delleveranse,tabell_anskaffelsens_innhold[Delleveranse],tabell_anskaffelsens_innhold[Kravsett for delleveranse],"ikke funnet") -> ikke funnet
D20: {=_xlfn.XLOOKUP(navn_delleveranse,tabell_anskaffelsens_innhold[Delleveranse],tabell_anskaffelsens_innhold[Kravsett 1]:tabell_anskaffelsens_innhold[Kravsett 4],"ikkefunnet")} -> ikkefunnet
D22: ATC | G22: =_xlfn.XLOOKUP(navn_delleveranse,tabell_anskaffelsens_innhold[Delleveranse],tabell_anskaffelsens_innhold[ATC],"ikke funnet") -> ikke funnet
D23: Virkestoff | G23: =_xlfn.XLOOKUP(navn_delleveranse,tabell_anskaffelsens_innhold[Delleveranse],tabell_anskaffelsens_innhold[Virkestoff],"ikke funnet") -> ikke funnet
D24: Undergruppe | G24: =_xlfn.XLOOKUP(navn_delleveranse,tabell_anskaffelsens_innhold[Delleveranse],tabell_anskaffelsens_innhold[Legemiddelformgruppe],"ikke funnet") -> ikke funnet
D25: Bruksområde | G25: =_xlfn.XLOOKUP(navn_delleveranse,tabell_anskaffelsens_innhold[Delleveranse],tabell_anskaffelsens_innhold[Bruksparameter Sykehusinnkjøp],"ikke funnet") -> ikke funnet
D27: Produktnavn og varenummer(som angitt i prisskjema, sett evt. inn flere linjer i rad 34)
D28: Varenr | E28: Varenavn
D36: =CONCATENATE("Krav for ",Dokumentnavn) -> Krav for Uregistrerte legemidler | F36: ="BETINGET FORMATERING ER SATT TIL: "&toggle_betingetFormatering&" (arkfane 'Lister')" -> BETINGET FORMATERING ER SATT TIL: ja (arkfane 'Lister')
D38: Oppdragsgivers kravspesifikasjon | K38: Tilbyderens besvarelse
B39: Anskaffelse | C39: Delleveranse | D39: Ref. | E39: Kravsett | F39: Kravetikett | G39: Beskrivelse av krav | H39: Krav- type | I39: Tildelingskriterier | J39: Utfyllende informasjon til tilbyder | K39: Velg svaralternativ i listen hvis mulig | L39: Utfyllende besvarelse | M39: Evt. lenke eller henvisning til vedlegg
B40: =navn_Anskaffelseskode -> 2301d | C40: =navn_delleveranse -> 0 | D40: 5.01 | E40: Generelle | F40: Prissetting | G40: Tilbudt pris skal angis i prisskjema per salgsenhet (varelinje/varenummer). | H40: S | J40: Se vedlegg 03 prisskjema, arkfane veiledning for riktig utfylling, og vedlegg 04 Bilag 04 administrative bestemmelser for beskrivelse av hvordan man registrerer varenummer i vareregisteret før avtalestart.
B41: =navn_Anskaffelseskode -> 2301d | C41: =navn_delleveranse -> 0 | D41: 5.02 | E41: Generelle | F41: Prissetting | G41: For produkter som har fått fastsatt en øvre innkjøpspris til bruk i spesialisthelsetjenesten gjennom positiv beslutning i Beslutningsforum for nye metoder, vil denne prisen utgjøre effektivt priskrav for spesialisthelsetjenesten. | H41: S
B42: =navn_Anskaffelseskode -> 2301d | C42: =navn_delleveranse -> 0 | D42: 5.03 | E42: Generelle | F42: Markedsføringstillatelse (MT) | G42: Tilbudt produkt skal ha godkjent markedsføringstillatelse i EU/EØS. | H42: S | J42: Oppgi MT-land og MT-nr i EU/EØS
B43: =navn_Anskaffelseskode -> 2301d | C43: =navn_delleveranse -> 0 | D43: 5.04 | E43: Generelle | F43: Opplæring og informasjon | G43: Godkjent SPC i søkbart format (ikke bildefil) skal være lastet opp i PharmaWeb innen tilbudsfrist, alternativt pakningsvedlegg der alle nødvendige opplysninger fremkommer. | H43: S | J43: Oppgi evt. lenke til SPC.
B44: =navn_Anskaffelseskode -> 2301d | C44: =navn_delleveranse -> 0 | D44: 5.05 | E44: Generelle | F44: Merking | G44: Tilbudt produkt skal ha latinske bokstaver på inner- og ytteremballasje. | H44: S | J44: Bilde av inner- og ytteremballasje lastes opp i PharmaWeb. Dersom bilde av emballasje ikke foreligger ved tilbudsfrist vurderes dette på bakgrunn av den dokumentasjon og eventuelt erfaring som foreligger.
B45: =navn_Anskaffelseskode -> 2301d | C45: =navn_delleveranse -> 0 | D45: 5.06 | E45: Generelle | F45: Likeverdighet | G45: Tilbyder skal inngi dokumentasjon for at tilbudt produkt er likeverdig med produkter som er angitt i Vedlegg 02 Kravspesifikasjon, arkfane 3 anskaffelsen og/eller Vedlegg 03 prisskjema. | H45: S | J45: Likeverdighet vil bli vurdert i hvert enkelt tilfelle ut fra pakningsstørrelse, styrke, sortiment (ut fra hvilke styrker og pakninger det er forbruk av i spesialisthelsetjenesten), formulering (inkludert innhold av hjelpestoffer som alkohol, sukker, propylenglykol for miksturer), inneremballasje, stabilitetsdata og administrasjonsform. Oppdragsgiver vil avvise tilbud der hvor likeverdighet ikke vurderes å foreligge etter en helhetsvurdering. Sammensetning av mikstur for eventuell bruk til barn vurderes i henhold til anbefalinger gitt av Neonatal & Paediatric Pharmacists Group, Newsletter No 61, 2016: http://nppg.org.uk/wp-content/uploads/2019/12/NPPG-61-amended.pdf.
B46: =navn_Anskaffelseskode -> 2301d | C46: =navn_delleveranse -> 0 | D46: 5.07 | E46: Generelle | F46: Leveringssikkerhet på produktnivå | G46: Leverandør skal her informere om hvor lang tid før avtalestart levering kan starte for varer med beredskap i B180 eller G2021, i henhold til leverandørens produksjonsplan. Dette kravet gjelder kun ny anbudsvinner, da eksisterende avtaleleverandør allerede har varer hos grossist og apotek/HF. | H46: S | J46: Angi antall dager før avtalestart som levering kan starte.
B47: =navn_Anskaffelseskode -> 2301d | C47: =navn_delleveranse -> 0 | D47: 5.08 | E47: Generelle | F47: Merking | G47: Tilbudt produkt bør ha ytteremballasje som er merket med GTIN i henhold til GS1-standard. | H47: B | I47: PP | J47: Besvares i Prisskjema. Leverandør fyller inn selv når det ikke er forhåndsutfylt (ett skjema totalt) Lenker til retningslinjer GTIN og GS1: https://www.gs1.org/docs/barcodes/GS1_DataMatrix_Guideline.pdf og https://www.gs1.org/docs/gsmp/healthcare/GS1_Healthcare_GTIN_Allocation_Rules.pdf | K47: Besvares i prisskjema
B48: =navn_Anskaffelseskode -> 2301d | C48: =navn_delleveranse -> 0 | D48: 5.09 | E48: Generelle | F48: Merking | G48: Tilbudt produkt bør ha dansk, svensk eller engelsk pakning. Sekundært tysk språk. | H48: B | I48: PP | J48: Angi språk på pakning og pakningsvedlegg.
B49: =navn_Anskaffelseskode -> 2301d | C49: =navn_delleveranse -> 0 | D49: 5.10 | E49: Generelle | F49: Merking | G49: Tilbudt produkt bør ha dansk, svensk eller engelsk SPC. Sekundært tysk språk. | H49: B | I49: PP | J49: Angi språk på SPC.
B50: =navn_Anskaffelseskode -> 2301d | C50: =navn_delleveranse -> 0 | D50: 5.11 | E50: Generelle | F50: Leveringssikkerhet på produktnivå | G50: Leverandøren bør ha inntil 6 mnd sikkerhetslager beregnet på det norske markedet av tilbudte produkter. | H50: B | I50: LP1 | J50: Angi antall dager sikkerhetslager som kommer i tillegg til skal-krav 4.1. Angi om det ikke gjelder alle produkter.
B51: =navn_Anskaffelseskode -> 2301d | C51: =navn_delleveranse -> 0 | D51: 5.12 | E51: Generelle | F51: Leveringssikkerhet på produktnivå | G51: Tilbudt produkt bør selges i Danmark, Sverige, Finland, Tyskland, Spania og/eller Frankrike. | H51: B | I51: LP2 | J51: Angi hvor mange av de seks angitte landene produktet selges i.
B52: =navn_Anskaffelseskode -> 2301d | C52: =navn_delleveranse -> 0 | D52: 5.13 | E52: Inj/inf | F52: Merking | G52: Tilbudt produkt bør ha inneremballasje som er merket med GTIN i henhold til GS1-standard. | H52: B | I52: PP | J52: Besvares i Prisskjema. Leverandør fyller inn selv når det ikke er forhåndsutfylt (ett skjema totalt) | K52: Besvares i prisskjema
B53: =navn_Anskaffelseskode -> 2301d | C53: =navn_delleveranse -> 0 | D53: 5.14 | E53: Inj/inf | F53: Merking | G53: Tilbudt produkt bør ha tydelig merking på inneremballasje med administrasjonsform, innhold, styrkebetegnelse i mg/1ml og fargekoder for forskjellige styrker. Videre bør tilbudt produkt ha en etikett for lesbarhet, framfor skrift trykket rett på gjennomsiktig bakgrunn. | H53: B | I53: PP | J53: Vurderes ut fra bilder av inneremballasje som lastes opp i PharmaWeb.
...

Sheet Lister
A1: Beskrivelse for ferdigstillelse av kravspesifikasjon
A3: SJEKKLISTE: | L3: TIPS OG TRIKS:
D4: Tabell med dokumentinfo fylles inn av prosjekt/fagrådgiver. Cellene skal være definert i excels navnebehandling. | L4: Nummerering av krav. Gjør ferdig krav først, kategoriser innen kravetikett. Lag nummer som tekst. Bruk apostrof ' først for eksempel: '5.01 '5.02 . Da kan liste trekkes og nummereres auto.
D5: (Passord til evt låste ark: 'excel')
A6: A - Fyll inn Anskaffelseskode, Anskaffelsesnavn, Dokumentnummer, Dokumentnav (kun i denne arkfanen 'Lister') | D6: Anskaffelseskode | E6: 2301d | G6: Eks: 2201h | H6: =navn_Anskaffelseskode&Dokumentnummer -> 2301d02 | L6: Tabeller er excel-tabeller. Legg til/fjern rader på "rett" måte.
D7: Anskaffelsesnavn | E7: Uregistrerte legemidler | G7: Eks: Klorheksidin
A8: B - Filnavn - Anskaffelsesnavn, Nummer, Leverandør annet? | D8: Dokumentnummer | E8: 02 | G8: Eks: 02.1 | L8: HUSK - man kan alltids overskrive og avvike fra malen dersom det er nødvendig, eller man finner tekniske feil.
A9: (B2 - Arkfane 2 bør leses igjennom og godkjennes) | D9: Dokumentnavn (navn på kravspek) | E9: Uregistrerte legemidler | G9: Eks: klorheksidin biocid
A10: C - Vektingsprosenter/tildelingskriterier settes i denne arkfanen('Lister') kolonne J, 'Vektingsprosent'. Arkfane 5 oppdateres da med farge automatisk og valideres for 100%. | D10: Informasjonen over vil tilsvare det som også bør ligge i filnavn. | F10: Eksempel filnavn: '[anskaffelse] [doknummer] [doknavn] [leverandørnavn].xlsx​'
D12: OBS - Denne informasjonen kan brukes for maskinell håndtering av filer(innlast/sammenslåing etc), men påvirker ikke dataene på andre måter.
A13: D - Kravtabell Produkt/delleveranse | D13: Navn på kravspesifikasjon kan være det samme som anskaffelsesnavn hvis det kun er én kravspek i anskaffelsen
A14: E - Delleveranser Arkfane 3 'Anskaffelsen' må være utfylt riktig. (Kravsett listemenyer populeres automatisk)
A15: F - Kravtabell Leverandør - Krav utarbeides og fylles inn riktig… | D15: OM TABELLEN MED LISTER (denne arkfanen)
D16: Det kan legges til flere kolonner i tabellen når det er behov for andre svaralternativer for utarbeidete krav.
A17: G - GJØR QA. Sjekk for banale feil i formatering ol. Test utfylling. | D17: Man kan slette eller legge til alternativer i listene som allerede foreligger ved behov for justering.
D18: Kobling til den riktige listen i tabellen gjøres ved bruk av funksjonen 'datavalidering', eller ved å kopiere en celle som har riktige svaralternativer fra før.
A19: H - SKJUL ARKFANE 'LISTER' (bør gjøres før utlysning) | D19: Bruk hjelpefunksjonen i excel eller spør en venn hvis man lurer på 'datavalidering'.
A21: I - Teknisk sjekk - Er informasjon i riktig tabellstruktur, tabellstørrelser, navnedefinisjoner osv | D21: OM TILDELINGSKRITERIER
D22: Tildelingskriterier: Fyll ut riktig vektingsprosent i tabellen, og skjul evt. rader i arkfane 4 og 5 der det velges 0% .
A23: J - Synliggjør formatering av kravtabeller(hvis ønsket) (manuelt endre tekst fra NEI til JA i cellen under før ferdigstillelse): | D23: Dersom det legges inn flere tildelingskriterier, må arkfane 4 og 5 oppdateres for en riktig framstilling.
D24: Vektingsprosent: Kontroller at det er 100% tilsammen (ligger også autovalidering i 4&5)
A25: (toggles kravtab formatering av/på) | D25: Farger som er benyttet kan finnes fram til f.eks ved å velge 'flere farger' i malingsbøtta mens man står i en riktig farget celle. Trykk OK for å velge samme farge.
A26: ja | D26: Er lagt inn automatisk fargeformatering på tildelingskriterier. (Dette ligger under 'Betinget formatering'-knapp)
D28: OM MALEN
D29: Legg inn delleveranser som omfattes av kravspesifikasjonen i arkfane 3 i grå tabell
D30: Legg inn/fjern/rediger krav til leverandør i arkfane 4
D31: Legg inn/fjern/rediger krav til produkt i arkfane 5
D32: Legg inn riktig kravnummer i ref.
D33: Krav i arkfane 5 som gjelder for alle produkter i kravspesifikasjonen nummereres 5.1.1 osv.
D34: Sett med krav som kun gjelder for enkelte grupper eller delleveranser nummereres 5.2.1 osv og 5.3.1 osv osv.
D35: Angi riktige sett med kravnummer for riktige delleveranser i arkfane 3 Anskaffelsen.
D36: Hvite celler skal stå tomme for at leverandør kan fylle ut.
D37: Veiledning til malen som står i hvite celler er satt med svart skriftfarge i stedet for blå, for at man skal slippe å endre tilbake til svart skrift.
D38: Sjul arkfane 'lister' før utlysning.
P40: OM ARKFANE 3 ANSKAFFELSEN - EKSEMPEL
A41: LISTER - Disse kan brukes for nedtrekksmenyer/drop downs i krav. | Q41: Definerer delleveransen (1) | R41: Definerer delleveransen (2) | S41: Definerer delleveransen (3) | T41: Definerer delleveransen (4) | X41: Vis til krav som gjelder for den aktuelle delleveranse
A42: Børkrav ja/nei | B42: B180 krav | C42: Bør-Krav til lager (LP1) | D42: Antall EU-land land med salg | E42: Skalkrav lager ved oppstart | F42: Skalkrav JA | G42: Kravtype | H42: MT-land i EU/EØS | I42: Tildelingskriterier | J42: Vektingsprosent | K42: Vektingsprosent alternativ 2 | L42: Skalkrav likeverdighet | M42: Emballasjetype tab/kaps | N42: Språk på pakning/SPC | O42: Papaverin | P42: Delleveranse | Q42: ATC | R42: Virkestoff | S42: Undergruppe | T42: Bruksområde Sykehusinnkjøp | U42: Parallell avtale Ja/nei | V42: Begrunnelse for parallell avtale | W42: Forventet lager hos grossist i Norge (B180, G2021) (inntil antall dager) | X42: Kravsett i arkfane 5
A43: Ja | B43: 60 | C43: 0 | D43: 1 | E43: Ja | F43: Ja | G43: S | H43: Belgia | I43: Pris (P) | J43: 0.35 | L43: SPC vedlagt | M43: Endose, elektronisk identifiserbar | N43: Dansk | O43: Inneholder ikke fenazon | P43: 1 | Q43: ABCDEF | R43: EKS1 Paracetamol | S43: Eks 1 infusjon | T43: Eks1 til barn | U43: Ja | V43: EKS1: Tilbyder rangert som nr 1 blir førstevalg for alle pasienter, det er allikevel behov for avtale med flere tilbydere for å dekke ulike medisinske behov. | W43: må avklares og innhentes info for aktuell anskaffelse | X43: (nr på krav som gjelder alle produkter + nr på krav som gjelder undergruppen infusjon)
A44: Nei | B44: 90 | C44: 30 | D44: 2 | E44: Tilbudte produkter er allerede i avtale og lager er bygd opp. | G44: B | H44: Bulgaria | I44: Brukervennlighet, pakninger og produktspekter (PP) | J44: 0.45 | L44: SPC og stabilitetsdata vedlagt | M44: Endose | N44: Svensk | O44: Inneholder fenazon | P44: 2 | Q44: ABCDEF | R44: EKS2 Paracetamol | S44: Eks 2 tablett/kapsel | T44: Eks2 ikke angitt | U44: Ja | V44: EKS2: Tilbyder rangert som nr 1 får tildelt 70% av markedet (2-3 RHF avhengig av forbruksmønster), og nr 2 får 30% av hensyn til beredskap. | W44: 180 | X44: (nr på krav som gjelder alle produkter + nr på krav som gjelder undergruppen tablett/kapsel)
B45: 120 | C45: 60 | D45: 3 | H45: Danmark | I45: Leveringssikkerhet: Lager (LP1) | J45: 0.15 | M45: Blister | N45: Engelsk
...
