Workbook
Name Anskaffelsesnavn: Lister!$E$7
Name Delleveranse: '5. Krav til prod.'!$H$10
Name Dokumentnavn: Lister!$E$9
Name Dokumentnummer: Lister!$E$8
Name kolonnematch_vektingsoppslag: [1]Vektingsoppslag!$D$1
Name kravtype: Lister!$G$43:$G$44
Name navn_Anskaffelseskode: Lister!$E$6
Name navn_atc: '5. Krav til prod.'!$H$21:$J$21
Name navn_bruksomrade: '5. Krav til prod.'!$H$24
Name navn_delleveranse: '5. Krav til prod.'!$H$17
Name navn_leverandornavn: '4. Krav overordnet nivå'!$H$18
Name navn_leverandornavn_produktfane: '5. Krav til prod.'!$H$16
Name navn_Navn_på_kravspesifikasjon: Lister!$E$10
Name navn_undergruppe: '5. Krav til prod.'!$H$23
Name navn_virkestoff: '5. Krav til prod.'!$H$22
Name oppfylt: Lister!$E$44:$E$44
Name toggle_betingetFormatering: Lister!$A$26

Sheet 1. Innhold
B1: =CONCATENATE(navn_Anskaffelseskode," Kravspesifikasjon ",Dokumentnummer," ", Dokumentnavn) -> 2507gj-1 Kravspesifikasjon Bilag 3 Anagrelid
B4: 1. Innhold
B6: Dette dokumentet består av:
B7: - Forklaring til kravspesifikasjonen
B8: - Anskaffelsens innhold
B9: - Krav til leverandøren
B10: - Krav til produktene

Sheet 2. Forklaring til kravspes.
B3: 2. Forklaring til kravspesifikasjonen
B5: Oppdragsgiver har angitt formålet med anskaffelsen og sine krav og behov i kravspesifikasjonen. Dette danner grunnlaget for Tilbyderens tilbud.
B6: I kravspesifikasjonen er det lagt vekt på å beskrive de behov som skal dekkes. Tilbyderen skal med utgangspunkt i kravspesifikasjonens rammer gi tilbud på forespurte produkter og beskrive hvordan kravene som stilles vil bli oppfylt. Tilbyderen er ansvarlig for at leveransen til enhver tid dekker kravene som er spesifisert.
B8: Tilbyderen skal besvare kravene direkte i kravspesifikasjonen og henvise til egne vedlegg ved behov. En tydelig og poengtert besvarelse vil lette Oppdragsgivers evaluering av tilbudet og sikre at korrekt informasjon blir brukt ved evalueringen. Det skal også her henvises til hvor i besvarelsen en eventuell utdypende beskrivelse, som kan ha betydning ved evalueringen, finnes. Henvisningen skal gi informasjon om navn på dokument, side og avsnitt. En besvarelse som for eksempel "se katalog/brosjyre" er ikke ønskelig, og kan føre til at tilbudet blir evaluert uten at Oppdragsgiver har kjennskap til alle egenskaper ved tilbudet/produktet.
B10: Kravene er utformet som SKAL-krav ("S") og BØR-krav ("B"). Dette kommer frem i kolonnen "kravtype" i tabellene.
B12: SKAL-krav er minstekrav til produktet. Alle SKAL-krav må være oppfylt for at produktet skal bli evaluert. Manglende oppfyllelse av SKAL-krav er et vesentlig avvik fra kravspesifikasjonen og vil medføre at tilbudet for det aktuelle produktet, eller den delkontrakten produktet tilhører, avvises fra konkurransen. SKAL-krav vil ikke bli evaluert utover om det er oppfylt eller ikke. Tilbyderen skal angi svar 'JA' eller velge et eventuelt alternativ i nedtrekksmenyen for om det tilbudte produkt oppfyller kravet som angis i punktet.
B14: BØR-krav er momenter som vil bli tillagt vekt i evalueringen av kvalitet og miljø. For BØR-krav vurderer Oppdragsgiver hvor godt de aktuelle kravene er oppfylt. Produkter som oppfyller BØR-kravene best, vil få flest poeng.
B16: Tilbyderen skal fylle ut de hvite feltene i kravspesifikasjonen. Tilbyderen skal ikke legge til eller slette verken linjer eller kolonner i kravspesifikasjonen.
B17: For produkter som er angitt som 'ikke relevant for anskaffelsen' i Bilag 02 prisskjema, er det ikke nødvendig å fylle ut kravspesifikasjon. Dersom det leveres tilbud på på produkt som ikke er likeverdig med legemidler oppført Bilag 02 prisskjema, bes leverandør legge til korrekt informasjon i Arkfane 3, i tomme grå rader merket med Delkontrakt 0.
B19: Oppdragsgiver har gitt hver linje i kravspesifikasjonen et unikt identifikasjonsnummer (kolonne D). Dette for lettere å kunne henvise til riktig punkt i kravspesifikasjonen ved behov.
B22: 2.1 - Leverandør
B23: Arkfane 'Krav til lev.' fylles kun ut én gang for hver Leverandør.
... B25: Det skal leveres én besvarelse per delleveranse (ATC/substans/undergruppe/bruksområde). Arkfane 'Krav til prod.'

Sheet 3. Anskaffelsen
B3: 3. Beskrivelse av anskaffelsens innhold
B5: Det ønskes tilbud på følgende delkontrakter innenfor området
B6: =CONCATENATE(navn_Anskaffelseskode," ",Dokumentnavn," ",Dokumentnummer," ",navn_Navn_på_kravspesifikasjon) -> 2507gj-1 Anagrelid Bilag 3 | L6: SKJULES? HVOR MANGE TRENGS? | M6: Kravsett for delkontrakt - se arkfane 5. Krav til prod
B7: Delkontrakt | C7: Kategori ernæring/inf skyll | D7: ATC | E7: Virkestoff Sykehusinnkjøp | F7: Legemiddelformgruppe | G7: Bruksparameter Sykehusinnkjøp | H7: Emballasjetype Sykehusinnkjøp | I7: Parallell avtale Ja/nei | J7: Begrunnelse for parallell avtale | K7: Forventet lager hos grossist i Norge (B180, G2021) (inntil antall dager) | L7: Kravsett for delleveranse | M7: Kravsett 1 | N7: Kravsett 2 | O7: Kravsett 3 | P7: Kravsett 4 | Q7: Kravsett 5 | R7: Kravsett 6 | S7: Kravsett 7 | T7: Kravsett 8 | U7: Kravsett 9 | V7: Kravsett 10
B8: 1 | D8: L01XX35 | E8: Anagrelid | F8: Tablett/kapsel | I8: Nei | L8: =tabell_anskaffelsens_innhold[[#This Row],[Kravsett 1]]&" "&tabell_anskaffelsens_innhold[[#This Row],[Kravsett 2]]&" "&tabell_anskaffelsens_innhold[[#This Row],[Kravsett 3]]&" "&tabell_anskaffelsens_innhold[[#This Row],[Kravsett 4]]&" "&tabell_anskaffelsens_innhold[[#This Row],[Kravsett 5]]&" "&tabell_anskaffelsens_innhold[[#This Row],[Kravsett 6]]&" "&tabell_anskaffelsens_innhold[[#This Row],[Kravsett 7]]&" "&tabell_anskaffelsens_innhold[[#This Row],[Kravsett 8]]&" "&tabell_anskaffelsens_innhold[[#This Row],[Kravsett 9]]&" "&tabell_anskaffelsens_innhold[[#This Row],[Kravsett 10]] -> Generelle Miljø Tablett/kapsel | M8: Generelle | N8: Miljø | O8: Tablett/kapsel
L9: =tabell_anskaffelsens_innhold[[#This Row],[Kravsett 1]]&" "&tabell_anskaffelsens_innhold[[#This Row],[Kravsett 2]]&" "&tabell_anskaffelsens_innhold[[#This Row],[Kravsett 3]]&" "&tabell_anskaffelsens_innhold[[#This Row],[Kravsett 4]]&" "&tabell_anskaffelsens_innhold[[#This Row],[Kravsett 5]]&" "&tabell_anskaffelsens_innhold[[#This Row],[Kravsett 6]]&" "&tabell_anskaffelsens_innhold[[#This Row],[Kravsett 7]]&" "&tabell_anskaffelsens_innhold[[#This Row],[Kravsett 8]]&" "&tabell_anskaffelsens_innhold[[#This Row],[Kravsett 9]]&" "&tabell_anskaffelsens_innhold[[#This Row],[Kravsett 10]]
L10: =tabell_anskaffelsens_innhold[[#This Row],[Kravsett 1]]&" "&tabell_anskaffelsens_innhold[[#This Row],[Kravsett 2]]&" "&tabell_anskaffelsens_innhold[[#This Row],[Kravsett 3]]&" "&tabell_anskaffelsens_innhold[[#This Row],[Kravsett 4]]&" "&tabell_anskaffelsens_innhold[[#This Row],[Kravsett 5]]&" "&tabell_anskaffelsens_innhold[[#This Row],[Kravsett 6]]&" "&tabell_anskaffelsens_innhold[[#This Row],[Kravsett 7]]&" "&tabell_anskaffelsens_innhold[[#This Row],[Kravsett 8]]&" "&tabell_anskaffelsens_innhold[[#This Row],[Kravsett 9]]&" "&tabell_anskaffelsens_innhold[[#This Row],[Kravsett 10]]
L11: =tabell_anskaffelsens_innhold[[#This Row],[Kravsett 1]]&" "&tabell_anskaffelsens_innhold[[#This Row],[Kravsett 2]]&" "&tabell_anskaffelsens_innhold[[#This Row],[Kravsett 3]]&" "&tabell_anskaffelsens_innhold[[#This Row],[Kravsett 4]]&" "&tabell_anskaffelsens_innhold[[#This Row],[Kravsett 5]]&" "&tabell_anskaffelsens_innhold[[#This Row],[Kravsett 6]]&" "&tabell_anskaffelsens_innhold[[#This Row],[Kravsett 7]]&" "&tabell_anskaffelsens_innhold[[#This Row],[Kravsett 8]]&" "&tabell_anskaffelsens_innhold[[#This Row],[Kravsett 9]]&" "&tabell_anskaffelsens_innhold[[#This Row],[Kravsett 10]]

Sheet 4. Krav overordnet nivå
E3: =CONCATENATE(navn_Anskaffelseskode," ",Dokumentnummer," Kravspesifikasjon ", Dokumentnavn) -> 2507gj-1 Bilag 3 Kravspesifikasjon Anagrelid
E5: 4. Krav på overordnet nivå
E6: NB: Det må leveres én besvarelse per leverandør
E7: Tildlingskriterier/underkriterier | H7: Vekting
E8: =Lister!I43 -> Pris (P) | H8: =Lister!J43 -> 0.5
E9: =Lister!I44 -> Brukervennlighet, pakninger og produktspekter (PP) | H9: =Lister!J44 -> 0.05
E10: =Lister!I45 -> Leveringssikkerhet: Lager (LP1) | H10: =Lister!J45 -> 0.12
E11: =Lister!I46 -> Leveringssikkerhet: Land (LP2) | H11: =Lister!J46 -> 0.03
E12: =Lister!I47 -> Miljø på leverandørnivå (ML1) | H12: =Lister!J47 -> 0.2
E13: =Lister!I48 -> Miljø på produktnivå (MP1) | H13: =Lister!J48 -> 0.1
E14: =Lister!I49 -> Pakninger og produktspekter (PP) | H14: =Lister!J49 -> 0 | I14: =Lister!K49 -> 0 | J14: =Lister!L49 -> 0
H15: SUM VEKTING <> 100% (FEILMELDING FJERNES NÅR LISTE = 100%) OPPDATER I EGET ARK!
E16: Informasjon om leverandør:
E18: Leverandørnavn:
E19: Kontaktperson for forsyningssikkerhet:
E20: E-postadresse ved leveringssvikt:
E21: Telefonnummer ved leveringssvikt:
E22: E-postadresse til logistikkavdeling:
E24: Oppdragsgivers kravspesifikasjon | K24: Tilbyderens besvarelse
B25: Anskaffelse | C25: Delkontrakt | D25: Leverandørnavn | E25: Ref. | F25: Kravsett | G25: Overskrift for krav | H25: Beskrivelse av krav | I25: Krav- type | J25: Tildelingskriterier | K25: Utfyllende informasjon til tilbyder | L25: Velg svaralternativ i listen | M25: Utfyllende besvarelse | N25: Evt. lenke eller henvisning til vedlegg
B26: 2407gj | C26: 0 | D26: 0 | E26: 4.01 | F26: Generelle | G26: Leveringssikkerhet | H26: Leverandøren forplikter seg til å opprette og forvalte 90 dager sikkerhetslager i EU/EØS av tilbudte produkter. Sikkerhetslageret skal være avsatt til det norske markedet. | I26: S | K26: Kontraktskrav til forvaltning av sikkerhetslager fremgår av rammeavtalen punkt 4.6.2.
B27: =navn_Anskaffelseskode -> 2507gj-1 | C27: =navn_delleveranse -> 1 | D27: =navn_leverandornavn -> 0 | E27: 4.02 | F27: Generelle | G27: Leveringssikkerhet | H27: Leverandør skal ha 3 måneders lager som Sykehusinnkjøp skal kunne revidere senest en måned før avtalestart. Ved varer med høyere beredskap enn 1 måned ved avtalestart skal man kunne fremvise en produksjonsplan senest 3 måneder før avtaleoppstart for nødvendig lageroppbygging. Dette kravet gjelder kun ny anbudsvinner, da eksisterende avtaleleverandør allerede har varer hos grossist og apotek/HF. | I27: S | K27: 30 dagers sikkerhetslager er inkludert.
B28: =navn_Anskaffelseskode -> 2507gj-1 | C28: =navn_delleveranse -> 1 | D28: =navn_leverandornavn -> 0 | E28: 4.03 | F28: Generelle | G28: Miljø på leverandørnivå | H28: Leverandøren bør ha implementert et miljøledelsessystem i virkestoffproduksjon for tilbudte produkter, som ivaretar risikovurderinger, miljørutiner, miljørevisjoner og sanksjoner ved brudd på avtale/miljørutine. For full uttelling skal miljøledelsessystemet være sertifisert av 3.part. | I28: B | J28: ML1 | K28: Angi svaralternativ. Spesifiser eventuelt hvilken 3. partssertifisering som er benyttet, hva som ikke er omfattet (risikovurdering, rutiner, miljørevisjoner og/eller sanksjoner), og om det foreligger en avtale om implementering av miljøledelsessystem med eventuell tredjepartsprodusent eller om leverandøren eier til produksjonen selv. Hvis man ikke eier produksjon eller har avtale om implementering av miljøledelsessystem med produsent, vil det ikke gi uttelling på kravet. Formålet med kravet er å oppnå minst mulig miljøbelastning ved produksjon av tilbudt produkt.
B29: =navn_Anskaffelseskode -> 2507gj-1 | C29: =navn_delleveranse -> 1 | D29: =navn_leverandornavn -> 0 | E29: 4.04 | F29: Generelle | G29: Miljø på leverandørnivå | H29: Leverandøren bør ha implementert et miljøledelsessystem i ferdigvareproduksjon for tilbudte produkter som ivaretar risikovurderinger, miljørutiner, miljørevisjoner og sanksjoner ved brudd på avtaler og miljørutiner. For full uttelling skal miljøledelsessystemet være sertifisert av 3.part. | I29: B | J29: ML1 | K29: Angi svaralternativ. Spesifiser eventuelt hvilken 3. partssertifisering som er benyttet, hva som ikke er omfattet (risikovurdering, rutiner, miljørevisjoner og/eller sanksjoner), og om det foreligger en avtale om implementering av miljøledelsessystem med eventuell tredjepartsprodusent eller om leverandøren eier til produksjonen selv. Hvis man ikke eier produksjon eller har avtale om implementering av miljøledelsessystem med produsent, vil det ikke gi uttelling på kravet. Formålet med kravet er å oppnå minst mulig miljøbelastning ved produksjon av tilbudt produkt.

Sheet 5. Krav til prod.
E3: =CONCATENATE(navn_Anskaffelseskode," ",Dokumentnummer," Kravspesifikasjon ", Dokumentnavn) -> 2507gj-1 Bilag 3 Kravspesifikasjon Anagrelid
E5: 5. Krav til produktene
E6: Tildlingskriterier/underkriterier | H6: Vekting
E7: =Lister!I43 -> Pris (P) | H7: =Lister!J43 -> 0.5
E8: =Lister!I44 -> Brukervennlighet, pakninger og produktspekter (PP) | H8: =Lister!J44 -> 0.05
E9: =Lister!I45 -> Leveringssikkerhet: Lager (LP1) | H9: =Lister!J45 -> 0.12
E10: =Lister!I46 -> Leveringssikkerhet: Land (LP2) | H10: =Lister!J46 -> 0.03
E11: =Lister!I47 -> Miljø på leverandørnivå (ML1) | H11: =Lister!J47 -> 0.2
E12: =Lister!I48 -> Miljø på produktnivå (MP1) | H12: =Lister!J48 -> 0.1
E13: =Lister!I49 -> Pakninger og produktspekter (PP) | H13: =Lister!J49 -> 0 | I13: =Lister!K49 -> 0 | J13: =Lister!L49 -> 0
H14: SUM VEKTING ER IKKE 100% (DENNE FEILMELDING FORSVINNER HVIS SUM I LISTE = 100%) OPPDATER I EGEN ARKFANE('Lister')!
E15: Informasjon om tilbudt produkt/produkter:
E16: Leverandørnavn:
E17: Delkontrakt (som angitt i ark 3) | H17: 1
E18: Kravsett for delkontrakt | G18: Kravsett | H18: =_xlfn.XLOOKUP(navn_delleveranse,tabell_anskaffelsens_innhold[Delkontrakt],tabell_anskaffelsens_innhold[Kravsett for delleveranse],"ikke funnet") -> Generelle Miljø Tablett/kapsel
E19: {=_xlfn.XLOOKUP(navn_delleveranse,tabell_anskaffelsens_innhold[Delkontrakt],tabell_anskaffelsens_innhold[Kravsett 1]:tabell_anskaffelsens_innhold[Kravsett 10],"ikkefunnet")} -> Generelle | F19: Miljø | G19: Tablett/kapsel | H19: 0 | I19: 0 | J19: 0 | K19: 0 | L19: 0 | M19: 0 | N19: 0
E20: Kategori ernæring/infusjons skyll | H20: =_xlfn.XLOOKUP(navn_delleveranse,tabell_anskaffelsens_innhold[Delkontrakt],tabell_anskaffelsens_innhold[Kategori ernæring/inf skyll],"ikke funnet") -> 0
E21: ATC | H21: =_xlfn.XLOOKUP(navn_delleveranse,tabell_anskaffelsens_innhold[Delkontrakt],tabell_anskaffelsens_innhold[ATC],"ikke funnet") -> L01XX35
E22: Virkestoff | H22: =_xlfn.XLOOKUP(navn_delleveranse,tabell_anskaffelsens_innhold[Delkontrakt],tabell_anskaffelsens_innhold[Virkestoff Sykehusinnkjøp],"ikke funnet") -> Anagrelid
E23: Bruksparameter | H23: =_xlfn.XLOOKUP(navn_delleveranse,tabell_anskaffelsens_innhold[Delkontrakt],tabell_anskaffelsens_innhold[Bruksparameter Sykehusinnkjøp],"ikke funnet")
E24: Emballasjetype | H24: =_xlfn.XLOOKUP(navn_delleveranse,tabell_anskaffelsens_innhold[Delkontrakt],tabell_anskaffelsens_innhold[Emballasjetype Sykehusinnkjøp],"ikke funnet")
E26: Produktnavn og varenummer(som angitt i prisskjema, sett evt. inn flere linjer i rad 31)
E27: Varenr | F27: Varenavn
E35: =CONCATENATE("Krav for ",Dokumentnavn) -> Krav for Anagrelid | G35: ="BETINGET FORMATERING (FOR Å FARGE KRAV SOM IKKE GJELDER VALGT DELLEVERANSE) ER SATT TIL: "&toggle_betingetFormatering&" (kan endres i arkfane 'Lister')" -> BETINGET FORMATERING (FOR Å FARGE KRAV SOM IKKE GJELDER VALGT DELLEVERANSE) ER SATT TIL: Ja (kan endres i arkfane 'Lister')
E37: Oppdragsgivers kravspesifikasjon | L37: Tilbyderens besvarelse
B38: Anskaffelse | C38: Delkontrakt | D38: Leverandørnavn | E38: Ref. | F38: Kravsett | G38: Kravetikett | H38: Beskrivelse av krav | I38: Krav- type | J38: Tildelingskriterier | K38: Utfyllende informasjon til tilbyder | L38: Velg svaralternativ i listen hvis mulig | M38: Utfyllende besvarelse | N38: Evt. lenke eller henvisning til vedlegg
B39: =navn_Anskaffelseskode -> 2507gj-1 | C39: =navn_delleveranse -> 1 | D39: =navn_leverandornavn_produktfane -> 0 | E39: 5.01 | F39: Generelle | G39: Prissetting | H39: Tilbudt pris skal innebære minimum 7,00 % rabatt målt mot maksimal AIP ved tilbudsfristens utløp. For produkter uten maksimal AIP ved tilbudsfrist må pris innebære minimum 7% rabatt etter at pris er godkjent av SLV. | I39: S | K39: Kontrolleres mot tilbudt GIP i Prisskjema og Maks AIP for tilbudt produkt eller tilsvarende produkt med fastsatt Maks AIP. Rabatten må være minimum 7,00 % uten avrunding, dvs 6,9 % er ikke godkjent. For informasjon om prissøknad se vedlegg Administrative bestemmelser. Gjelder kun for produkter med MT i Norge og fastsatt maks AIP. | L39: Besvares i prisskjema
B40: =navn_Anskaffelseskode -> 2507gj-1 | C40: =navn_delleveranse -> 1 | D40: =navn_leverandornavn_produktfane -> 0 | E40: 5.02 | F40: Generelle | G40: Prissetting | H40: Tilbudt pris skal angis i prisskjema per varenummer (salgsenhet). | I40: S | K40: Dersom tilbudt produkt ikke er forhåndsutfylt i prisskjema, eller at varenummeret tilhører en annen leverandør enn tilbyder, skal tilbyder fylle ut en ny linje i prisskjema og angi riktig informasjon om tilbyder/varen i de oppførte kolonnene. Varenummer skal da være blank, ettersom det ikke er tildelt norsk varenummer enda. Se vedlegg 04 Bilag 04 administrative bestemmelser for beskrivelse av hvordan man registrerer varenummer i vareregisteret før avtalestart.
B41: =navn_Anskaffelseskode -> 2507gj-1 | C41: =navn_delleveranse -> 1 | D41: =navn_leverandornavn_produktfane -> 0 | E41: 5.03 | F41: Generelle | G41: Prissetting | H41: For produkter som har fått fastsatt en øvre innkjøpspris til bruk i spesialisthelsetjenesten gjennom positiv beslutning i Beslutningsforum for nye metoder, vil denne prisen utgjøre effektivt priskrav for spesialisthelsetjenesten. | I41: S
B42: =navn_Anskaffelseskode -> 2507gj-1 | C42: =navn_delleveranse -> 1 | D42: =navn_leverandornavn_produktfane -> 0 | E42: 5.04 | F42: Generelle | G42: Markedsføringstillatelse (MT) | H42: Tilbudt produkt skal ha gyldig MT i Norge innen tilbudsfristens utløp. For parallellimportert produkt skal tilbudt produkt ha MT i EU/EØS innen tilbudsfristens utløp, og ha gyldig MT i Norge innen 4 måneder etter tildelingsdato. Dersom tilbyder inngir tilbud på et produkt uten MT i Norge ved tilbudsfristens utløp, skal tilbyder dokumentere at søknad om MT for tilbudt produkt er inngitt til aktuell regulatorisk myndighet forut for tilbudsfristens utløp, eller at tilbudt produkt har godkjent MT i EU/EØS innen tilbudsfristens utløp. For legemiddelformer som er nye i markedet og som planlegges tatt i bruk i begrenset grad (bruksklare infusjonsløsninger), skal tilbudt produkt ha gyldig MT i Norge innen avtalestart. | I42: S | K42: Godkjent SPC på legemiddelsok.no. eller kopi av ev. søknad, samt evt preliminær SPC vedlegges tilbudet. For parallellimportert produkt vedlegges SPC for produkt som det planlegges å søke MT for, samt bilde og plan for merking av inneremballasjen. Oppdragsgiver forbeholder seg retten til å inngå en parallell avtale dersom vinner ikke har fått MT i Norge ved tidspunktet for tildeling. Dersom vinner ikke har fått MT innen fristen, vil avtalen med vinner sies opp og parallell avtaleleverandør forespurt om å overta leveransen.
B43: =navn_Anskaffelseskode -> 2507gj-1 | C43: =navn_delleveranse -> 1 | D43: =navn_leverandornavn_produktfane -> 0 | E43: 5.05 | F43: Generelle | G43: Opplæring og informasjon | H43: Tilbyder skal, på forespørsel kunne levere informasjonsmateriale som viser korrekt bruk av tilbudt produkt, herunder tilstrekkelig informasjon om utblandning, volum, brukstid etter utblanding og administrering. | I43: S
B44: =navn_Anskaffelseskode -> 2507gj-1 | C44: =navn_delleveranse -> 1 | D44: =navn_leverandornavn_produktfane -> 0 | E44: 5.06 | F44: Generelle | G44: Merking | H44: Tilbudt produkt skal ha ytteremballasje som er merket med GTIN i henhold til GS1-standard. | I44: S | K44: Besvares i Prisskjema. Leverandør fyller inn selv når det ikke er forhåndsutfylt (ett skjema totalt) Lenker til retningslinjer GTIN og GS1: https://www.gs1.org/docs/barcodes/GS1_DataMatrix_Guideline.pdf og https://www.gs1.org/docs/gsmp/healthcare/GS1_Healthcare_GTIN_Allocation_Rules.pdf | L44: Besvares i prisskjema | N44: Prisskjema
B45: =navn_Anskaffelseskode -> 2507gj-1 | C45: =navn_delleveranse -> 1 | D45: =navn_leverandornavn_produktfane -> 0 | E45: 5.07 | F45: Generelle | G45: Likeverdighet | H45: Tilbyder skal inngi dokumentasjon for at tilbudt produkt er likeverdig med produkter som er angitt i Bilag 2 prisskjema. | I45: S | K45: Likeverdighet vil bli vurdert i hvert enkelt tilfelle ut fra generisk byttekode, pakningsstørrelse, styrke, sortiment (ut fra hvilke styrker og pakninger det er forbruk av i spesialisthelsetjenesten), formulering, inneremballasje, stabilitetsdata og administrasjonsform. Oppdragsgiver vil avvise tilbud der hvor likeverdighet ikke vurderes å foreligge etter en helhetsvurdering. Dersom leverandøren har ingitt tilbud på et produkt som hører inn under anskaffelsens område, men som ikke er likeverdig med produkter angitt i Bilag 2 Prisskjema, skal en begrunnelse for tilbudet fylles ut i arkfane 4. Krav til lev.
B46: =navn_Anskaffelseskode -> 2507gj-1 | C46: =navn_delleveranse -> 1 | D46: =navn_leverandornavn_produktfane -> 0 | E46: 5.08 | F46: Generelle | G46: Sortiment | H46: Tilbyders sortiment skal angis i prisskjema. | I46: S | K46: Det er anleding til å inngi pristilbud på varelinjer som er satt som ikke relevant for anskaffelsen i prisskjema. Pakninger som er angitt som ikke relevante, vil ikke bli evaluert. Det er likevel ønskelig at leverandør inngir tilbud på hele sitt sortiment innenfor en delleveranse. Dette av hensyn til håndtering av eventuell leveringssvikt, samt kundens behov for sortimentsbredde, og pasientspesifikke medisinske behov. Vinnende tilbyder kan bli tildelt kontrakt på hele det tilbudte sortimentet.
B47: =navn_Anskaffelseskode -> 2507gj-1 | C47: =navn_delleveranse -> 1 | D47: =navn_leverandornavn_produktfane -> 0 | E47: 5.09 | F47: Generelle | G47: Leveringssikkerhet på produktnivå | H47: Produktet bør selges i Danmark, Sverige, Finland, Tyskland, Spania og Frankrike. | I47: B | J47: LP2 | K47: Angi hvor mange av de seks angitte landene produktet selges i.
B48: =navn_Anskaffelseskode -> 2507gj-1 | C48: =navn_delleveranse -> 1 | D48: =navn_leverandornavn_produktfane -> 0 | E48: 5.10 | F48: Generelle | G48: Leveringssikkerhet på produktnivå | H48: Leverandør bør oppgi land og navn på selskapet/selskapene som produserer ferdigvare av tilbudt produkt. | I48: B | J48: LP2 | K48: Angi svaralternativ og spesifiser eventuelt land, navn, adresse (kordinater) eller Global location number (GLN-kode) på selskap. Formålet med kravet er å vurdere risiko for leveringssvikt, samt planlegge og iverksette eventuelle tiltak for å sikre stabil levering over tid.
B49: =navn_Anskaffelseskode -> 2507gj-1 | C49: =navn_delleveranse -> 1 | D49: =navn_leverandornavn_produktfane -> 0 | E49: 5.11 | F49: Generelle | G49: Leveringssikkerhet på produktnivå | H49: Leverandøren bør oppgi land og navn på selskapet/selskapene som produserer virkestoff(ene) i tilbudt produkt. | I49: B | J49: LP2 | K49: Angi svaralternativ og spesifiser eventuelt land, navn, adresse (kordinater) eller Global location number (GLN-kode) på selskap. Formålet med kravet er å vurdere risiko for leveringssvikt, samt planlegge og iverksette eventuelle tiltak for å sikre stabil levering over tid.
B50: =navn_Anskaffelseskode -> 2507gj-1 | C50: =navn_delleveranse -> 1 | D50: =navn_leverandornavn_produktfane -> 0 | E50: 5.12 | F50: Generelle | G50: Leveringssikkerhet på produktnivå | H50: Tilbudt produkt bør ha fellesnordisk pakning | I50: B | J50: LP2 | K50: Angi ja eller nei for om det er fellesnordisk pakning eller ikke.
B51: =navn_Anskaffelseskode -> 2507gj-1 | C51: =navn_delleveranse -> 1 | D51: =navn_leverandornavn_produktfane -> 0 | E51: 5.13 | F51: Generelle | G51: Leveringssikkerhet på produktnivå | H51: Leverandøren bør ha inntil 6 mnd sikkerhetslager beregnet på det norske markedet av tilbudte produkter. | I51: B | J51: LP1 | K51: Angi antall dager sikkerhetslager som kommer i tillegg til skal-krav 4.01 Leveringssikkerhet. Angi om det ikke gjelder alle produkter.
B52: =navn_Anskaffelseskode -> 2507gj-1 | C52: =navn_delleveranse -> 1 | D52: =navn_leverandornavn_produktfane -> 0 | E52: 5.14 | F52: Miljø | G52: Miljø på produktnivå | H52: Tilbudt produkt bør produseres av virkestoffprodusent og ferdigvareprodusent som har rutiner for å minimere mengde og konsentrasjon av virkestoff i avløpsvann. | I52: B | J52: MP | K52: Angi svaralternativ. Rutiner for avløpsvann må være spesifisert i avtale med eventuell tredjepartsprodusent for å kunne gi uttelling. Rutine skal dokumenteres på forespørsel. Formålet med kravet er å oppnå minst mulig miljøbelastning ved produksjon av tilbudt produkt.
...

Sheet Lister
A1: Beskrivelse for ferdigstillelse av kravspesifikasjon
A3: SJEKKLISTE: | L3: TIPS OG TRIKS:
D4: Tabell med dokumentinfo fylles inn av prosjekt/fagrådgiver. Cellene skal være definert i excels navnebehandling. | L4: Nummerering av krav. Gjør ferdig krav først, kategoriser innen kravetikett. Lag nummer som tekst. Bruk apostrof ' først for eksempel: '5.01 '5.02 . Da kan liste trekkes og nummereres auto.
D5: (Passord til evt låste ark: 'excel')
A6: A - Fyll inn Anskaffelseskode, Anskaffelsesnavn, Dokumentnummer, Dokumentnav (kun i denne arkfanen 'Lister') | D6: Anskaffelseskode | E6: 2507gj-1 | G6: Eks: 2201h | H6: =navn_Anskaffelseskode&Dokumentnummer -> 2507gj-1Bilag 3 | L6: Tabeller er excel-tabeller. Legg til/fjern rader på "rett" måte.
D7: Anskaffelsesnavn | E7: Anagrelid | G7: Eks: Klorheksidin
A8: B - Filnavn - Anskaffelsesnavn, Nummer, Leverandør annet? | D8: Dokumentnummer | E8: Bilag 3 | G8: Eks: Bilag 3 | L8: HUSK - man kan alltids overskrive og avvike fra malen dersom det er nødvendig, eller man finner tekniske feil.
A9: (B2 - Arkfane 2 bør leses igjennom og godkjennes) | D9: Dokumentnavn (navn på kravspek) | E9: Anagrelid | G9: Eks: klorheksidin biocid
A10: C - Vektingsprosenter/tildelingskriterier settes i denne arkfanen('Lister') kolonne J, 'Vektingsprosent'. Arkfane 5 oppdateres da med farge automatisk og valideres for 100%. | D10: Informasjonen over vil tilsvare det som også bør ligge i filnavn. | F10: Eksempel filnavn: '[anskaffelse] [doknummer] [doknavn] [leverandørnavn].xlsx​'
L11: OM ARKFANE 3 ANSKAFFELSEN - EKSEMPEL
D12: OBS - Denne informasjonen kan brukes for maskinell håndtering av filer(innlast/sammenslåing etc), men påvirker ikke dataene på andre måter. | M12: Definerer delkontrakten 1 (skjules i de fleste anskaffelser) | N12: Definerer delkontrakten 2 | O12: Definerer delkontrakten 3 | P12: Definerer delkontrakten 4 | Q12: Definerer delkontrakten 5 | R12: Definerer delkontrakten 6 | V12: Vis til krav som gjelder for den aktuelle delleveranse
A13: D - Kravtabell Produkt/delkontrakt | D13: Navn på kravspesifikasjon kan være det samme som anskaffelsesnavn hvis det kun er én kravspek i anskaffelsen | L13: Delkontrakt | M13: Kategori ernæring/inf skyll | N13: ATC | O13: Virkestoff Sykehusinnkjøp | P13: Legemiddelformgruppe | Q13: Bruksparameter Sykehusinnkjøp | R13: Emballasjetype Sykehusinnkjøp | S13: Parallell avtale Ja/nei | T13: Begrunnelse for parallell avtale | U13: Forventet lager hos grossist i Norge (B180, G2021) (inntil antall dager) | V13: Kravsett i arkfane 5
A14: E - Delkontrakter Arkfane 3 'Anskaffelsen' må være utfylt riktig. (Kravsett listemenyer populeres automatisk) | L14: 1 | N14: ABCDEF | O14: EKS1 Paracetamol | P14: Eks 1 infusjon | Q14: Eks1 til barn | S14: Ja | T14: EKS1: Tilbyder rangert som nr 1 blir førstevalg for alle pasienter, det er allikevel behov for avtale med flere tilbydere for å dekke ulike medisinske behov. | U14: må avklares og innhentes info for aktuell anskaffelse | V14: Velg fra automatisk generert liste
A15: F - Kravtabell Leverandør - Krav utarbeides og fylles inn riktig… | D15: OM TABELLEN MED LISTER (denne arkfanen) | L15: 2 | N15: ABCDEF | O15: EKS2 Paracetamol | P15: Eks 2 tablett/kapsel | R15: Endose, elektronisk identifiserbar | S15: Ja | T15: EKS2: Tilbyder rangert som nr 1 får tildelt 70% av markedet (2-3 RHF avhengig av forbruksmønster), og nr 2 får 30% av hensyn til beredskap. | U15: 180 | V15: Velg fra automatisk generert liste
D16: Det kan legges til flere kolonner i tabellen når det er behov for andre svaralternativer for utarbeidete krav.
A17: G - GJØR QA. Sjekk for banale feil i formatering ol. Test utfylling. | D17: Man kan slette eller legge til alternativer i listene som allerede foreligger ved behov for justering.
D18: Kobling til den riktige listen i tabellen gjøres ved bruk av funksjonen 'datavalidering', eller ved å kopiere en celle som har riktige svaralternativer fra før.
A19: H - SKJUL ARKFANE 'LISTER' (bør gjøres før utlysning) | D19: Bruk hjelpefunksjonen i excel eller spør en venn hvis man lurer på 'datavalidering'.
A21: I - Teknisk sjekk - Er informasjon i riktig tabellstruktur, tabellstørrelser, navnedefinisjoner osv | D21: OM TILDELINGSKRITERIER
D22: Tildelingskriterier: Fyll ut riktig vektingsprosent i tabellen, og skjul evt. rader i arkfane 4 og 5 der det velges 0% .
A23: J - Synliggjør formatering av kravtabeller(hvis ønsket) (manuelt endre tekst fra NEI til JA i cellen under før ferdigstillelse): | D23: Dersom det legges inn flere tildelingskriterier, må arkfane 4 og 5 oppdateres for en riktig framstilling.
D24: Vektingsprosent: Kontroller at det er 100% tilsammen (ligger også autovalidering i 4&5)
A25: Skriv JA eller NEI for å skru betinget formatering av eller på i arkfane '5.Krav til prod') | D25: Farger som er benyttet kan finnes fram til f.eks ved å velge 'flere farger' i malingsbøtta mens man står i en riktig farget celle. Trykk OK for å velge samme farge.
A26: Ja | D26: Er lagt inn automatisk fargeformatering på tildelingskriterier. (Dette ligger under 'Betinget formatering'-knapp)
D28: OM MALEN
D29: Legg inn delkontrakter som omfattes av kravspesifikasjonen i arkfane 3 i grå tabell
D30: Legg inn/fjern/rediger krav til leverandør i arkfane 4
D31: Legg inn/fjern/rediger krav til produkt i arkfane 5
D32: Legg inn riktig kravnummer i ref.
D33: Krav i arkfane 5 som gjelder for alle produkter i kravspesifikasjonen nummereres 5.1.1 osv.
D34: Sett med krav som kun gjelder for enkelte grupper eller delleveranser nummereres 5.2.1 osv og 5.3.1 osv osv.
D35: Angi riktige sett med kravnummer for riktige delkontrakter i arkfane 3 Anskaffelsen.
D36: Hvite celler skal stå tomme for at leverandør kan fylle ut.
D37: Veiledning til malen som står i hvite celler er satt med svart skriftfarge i stedet for blå, for at man skal slippe å endre tilbake til svart skrift.
D38: Sjul arkfane 'lister' før utlysning.
A41: LISTER - Disse kan brukes for nedtrekksmenyer/drop downs i krav.
A42: Børkrav ja/nei | B42: B180 krav | C42: Bør-Krav til lager (LP1) | D42: Antall EU-land land med salg | E42: Skalkrav lager ved oppstart | F42: Skalkrav JA | G42: Kravtype | H42: MT-land i EU/EØS | I42: Tildelingskriterier | J42: Vektingsprosent | K42: Vektingsprosent alternativ 2 | L42: Vektingsprosent alternativ 3 | M42: Inneremballasjetype | N42: Skal-Krav MT | O42: Miljøledelse | P42: Pnec | Q42: Rutine avløpsvann | R42: Rutine avfall | S42: Plass i avfall | T42: Oppgitt land | U42: Oppbevaringsbetingelser | V42: Beskyttelse mot knusing | W42: Tørrstoff | X42: Rekonstitusjonstrinn | Y42: Utblanding | Z42: Sortiment | AA42: Egnet for pakking | AB42: Likeverdighet Leverandør | AC42: Likeverdighet produkt | AD42: Egnethet pakking/robot
A43: Ja | B43: 60 | C43: 0 | D43: 1 | E43: Ja | F43: Ja | G43: S | H43: Belgia | I43: Pris (P) | J43: 0.5 | K43: 0.35 | L43: 0.55 | M43: Elektronisk identifiserbar endose | N43: Har MT | O43: Implementert miljøledelsessystem for risiko, rutiner, revisjoner og sanksjoner som er sertifisert av 3. part for alle tilbudte produkter. (Spesifiser hvilken sertifisering. Eks. ISO 14001) | P43: Både virkestoff-og ferdigvareprodusent har rutine for å oppnå PNEC (Spesifiser PNEC og kilde til PNEC som benyttes). | Q43: Både virkestoff-og ferdigvareprodusent har rutine for avløpsvann. | R43: Både virkestoff-og ferdigvareprodusent har rutine for avfall. | S43: Kan komprimeres helt flat av bruker, og inneholder ingen luft eller luftlommer når den er komprimert. (Eksempelvis emballasje av kartong) | T43: Navn, adresse og land er oppgitt (spesifiseres ett eller flere navn, adresser og land) | U43: Kan oppbevares i romtemp uten lysbeskyttelse hele holdbarhetstiden | V43: Krymeplast og forsterket base | W43: Kan løses opp i fortynningsvæsken og har oppløsningstid på 1 minutt eller mindre. | X43: Bruksklar | Y43: Data for utblanding i infusjonspose medfølger tilbudet (angi henvisning). | Z43: Ja | AA43: Vareprøve eller stabilitetsdata sendes på forespørsel. | AB43: Tilbudet inneholder kun likeverdige produkter med det som er oppført i Bilag 02 Prisskjema. | AC43: Ja | AD43: Tilbudt produkt er i eksisterende avtale og kjent for oppdragsgiver.
A44: Nei | B44: 90 | C44: 30 | D44: 2 | E44: Tilbudte produkter er allerede i avtale og lager er bygd opp. | G44: B | H44: Bulgaria | I44: Brukervennlighet, pakninger og produktspekter (PP) | J44: 0.05 | K44: 0.2 | L44: 0 | M44: Endose | N44: Har søkt MT (spesifiser) | O44: Implementert miljøledelsessystem for risiko, rutiner, revisjoner og sanksjoner som ikke er sertifisert av 3. part for alle tilbudte produkter. | P44: Kun virkestoffprodusent har rutine for å oppnå PNEC (Spesifiser PNEC og kilde til PNEC som benyttes). | Q44: Kun virkestoffprodusent har rutine for avløpsvann. | R44: Kun virkestoffprodusent har rutine for avlfall. | S44: Kan komprimeres av bruker, men emballasjen inneholder noe luft eller det oppstår luftlommer rundt emballasjen når den er komprimert. (Eksempelvis emballasje av hard plast). | T44: Kun land er oppgitt (spesifiseres ett eller flere land) | U44: Må oppbevares kjølig i hele holdbarhetstiden | V44: Krympeplast | W44: Kan løses opp i fortynningsvæsken og har oppløsningstid på over 1 minutt. | X44: Konsentrat som tilsettes direkte i fortynningsvæsken | Z44: Delvis (spesifiser eller henvisning til prisskjema) | AB44: Tilbudet inneholder ett eller flere produkter som ikke er likeverdig med produkter oppført i Bilag 02 Prisskjema. (Spesifiser begrunnelse og henvisning til vedlagt dokumentasjon). | AC44: Begrunnelse inngitt i arkfane 4. Krav til lev. | AD44: Vareprøve/tekniske spesifikasjoner/bilde sendes på forespørsel.
B45: 120 | C45: 60 | D45: 3 | H45: Danmark | I45: Leveringssikkerhet: Lager (LP1) | J45: 0.12 | K45: 0.12 | L45: 0.12 | M45: Blister der hver tablett er merket (spesisfiser) | O45: Delvis implementert miljøledelsessystem (Spesifiser hvilke deler/produkter som ikke er implementert og/eller sertifisert, og spesifiser eventuelt hvilken sertifisering). | P45: Kun ferdigvareprodusent har rutine for å oppnå PNEC. (Spesifiser PNEC og kilde til PNEC som benyttes). | Q45: Kun ferdigvareprodusent har rutine for avløpsvann. | R45: Kun ferdigvareprodusent har rutine for avfall. | S45: Kan ikke komprimeres. (Eksempelvis emballasje av hard plast eller glass). | T45: Navn og land er ikke oppgitt. | U45: Må oppbevares kjølig etter utblanding | V45: Annet (spesifiseres) | W45: Kan ikke løses opp i fortynningsvæsken og har oppløsningstid på 1 minutt eller mindre. | X45: Konsentrat med mer enn ett rekonstitusjonstrinn | Z45: Nei
...
